{
 "cells": [
  {
   "cell_type": "code",
   "execution_count": 1,
   "id": "d7bfa5d5-6129-4142-bb7d-5572b78c0876",
   "metadata": {},
   "outputs": [
    {
     "name": "stdout",
     "output_type": "stream",
     "text": [
      "Using TensorFlow backend\n"
     ]
    },
    {
     "name": "stderr",
     "output_type": "stream",
     "text": [
      "2023-10-18 13:17:39.916330: I tensorflow/core/platform/cpu_feature_guard.cc:182] This TensorFlow binary is optimized to use available CPU instructions in performance-critical operations.\n",
      "To enable the following instructions: AVX2 FMA, in other operations, rebuild TensorFlow with the appropriate compiler flags.\n",
      "2023-10-18 13:17:40.980744: W tensorflow/compiler/tf2tensorrt/utils/py_utils.cc:38] TF-TRT Warning: Could not find TensorRT\n",
      "/global/home/users/mfong/anaconda3/lib/python3.8/site-packages/pandas/core/computation/expressions.py:20: UserWarning: Pandas requires version '2.7.3' or newer of 'numexpr' (version '2.7.1' currently installed).\n",
      "  from pandas.core.computation.check import NUMEXPR_INSTALLED\n"
     ]
    }
   ],
   "source": [
    "# pretrain MLP using the new dataloader\n",
    "\n",
    "import sys\n",
    "import os\n",
    "os.environ[\"CUDA_VISIBLE_DEVICES\"] = \"1\"\n",
    "\n",
    "from typing import List\n",
    "import h5py\n",
    "from torch.utils.data import Dataset, DataLoader\n",
    "import numpy as np\n",
    "import preprocessing\n",
    "from tqdm import tqdm\n",
    "import keras_core as keras\n",
    "from keras_core import layers\n",
    "from keras_core import ops\n",
    "import matplotlib.pyplot as plt\n",
    "\n",
    "from data_utils import preprocess_data, H5Dataset"
   ]
  },
  {
   "cell_type": "code",
   "execution_count": 2,
   "id": "7372878f-3077-4cc3-9195-8f7a349bcf6c",
   "metadata": {},
   "outputs": [],
   "source": [
    "train_dir = \"/global/ml4hep/spss/mfong/transfer_learning/delphes_train/\"\n",
    "train_dir_preprocess = \"/global/ml4hep/spss/mfong/transfer_learning/delphes_train_processed/\"\n",
    "train_filepaths = [train_dir + x for x in os.listdir(train_dir)]\n",
    "# preprocess_data(train_filepaths, train_dir_preprocess, force=False)\n",
    "train_preprocess_file_names = os.listdir(train_dir_preprocess)\n",
    "train_preprocess_filepaths = [train_dir_preprocess + name for name in train_preprocess_file_names]"
   ]
  },
  {
   "cell_type": "code",
   "execution_count": 3,
   "id": "25ff82d9-c59b-48d1-a0c7-8022029ad8b7",
   "metadata": {},
   "outputs": [
    {
     "data": {
      "text/plain": [
       "20000000"
      ]
     },
     "execution_count": 3,
     "metadata": {},
     "output_type": "execute_result"
    }
   ],
   "source": [
    "train_dataset = H5Dataset(train_preprocess_filepaths[:4], transform=None)\n",
    "train_dataloader = DataLoader(train_dataset, batch_size=256, shuffle=False)\n",
    "len(train_dataset)"
   ]
  },
  {
   "cell_type": "code",
   "execution_count": 4,
   "id": "52ae5aa3-34a1-4fc0-8799-eabcbc1b23c9",
   "metadata": {},
   "outputs": [
    {
     "data": {
      "text/plain": [
       "5000000"
      ]
     },
     "execution_count": 4,
     "metadata": {},
     "output_type": "execute_result"
    }
   ],
   "source": [
    "test_dataset = H5Dataset(train_preprocess_filepaths[5:6], transform=None)\n",
    "test_dataloader = DataLoader(test_dataset, batch_size=256, shuffle=False)\n",
    "len(test_dataset)"
   ]
  },
  {
   "cell_type": "code",
   "execution_count": null,
   "id": "a0c18b20-14f2-478e-85bf-a7fd2544dc7e",
   "metadata": {},
   "outputs": [],
   "source": []
  },
  {
   "cell_type": "code",
   "execution_count": 5,
   "id": "332b2ed0-e2be-4536-b8bc-af847edb3ef6",
   "metadata": {},
   "outputs": [],
   "source": [
    "import tensorflow as tf\n",
    "from tensorflow import keras\n",
    "from tensorflow.keras.models import Sequential\n",
    "from tensorflow.keras.layers import Dense\n",
    "from tensorflow.keras.layers import Flatten"
   ]
  },
  {
   "cell_type": "code",
   "execution_count": 6,
   "id": "c0f938a0-a48a-4885-8d4a-36bf69afd596",
   "metadata": {},
   "outputs": [
    {
     "name": "stderr",
     "output_type": "stream",
     "text": [
      "2023-10-18 13:17:48.277214: I tensorflow/core/common_runtime/gpu/gpu_device.cc:1639] Created device /job:localhost/replica:0/task:0/device:GPU:0 with 33892 MB memory:  -> device: 0, name: NVIDIA A40, pci bus id: 0000:41:00.0, compute capability: 8.6\n"
     ]
    }
   ],
   "source": [
    "model = Sequential()\n",
    "model.add(Dense(64, input_shape=(200*7,), activation='relu'))\n",
    "model.add(Flatten())\n",
    "model.add(Dense(8, activation='relu'))\n",
    "model.add(Dense(1, activation='sigmoid'))\n",
    "model.compile(loss='binary_crossentropy', optimizer='adam', metrics=['accuracy', \"AUC\"])"
   ]
  },
  {
   "cell_type": "code",
   "execution_count": 7,
   "id": "ea88f616-bd3e-4378-91ac-acf6aed41413",
   "metadata": {},
   "outputs": [
    {
     "ename": "ValueError",
     "evalue": "Failed to find data adapter that can handle input: <class 'torch.utils.data.dataloader.DataLoader'>, <class 'NoneType'>",
     "output_type": "error",
     "traceback": [
      "\u001b[0;31m---------------------------------------------------------------------------\u001b[0m",
      "\u001b[0;31mValueError\u001b[0m                                Traceback (most recent call last)",
      "Cell \u001b[0;32mIn[7], line 1\u001b[0m\n\u001b[0;32m----> 1\u001b[0m history \u001b[38;5;241m=\u001b[39m \u001b[43mmodel\u001b[49m\u001b[38;5;241;43m.\u001b[39;49m\u001b[43mfit\u001b[49m\u001b[43m(\u001b[49m\u001b[43mtrain_dataloader\u001b[49m\u001b[43m,\u001b[49m\u001b[43m \u001b[49m\u001b[43mbatch_size\u001b[49m\u001b[38;5;241;43m=\u001b[39;49m\u001b[38;5;241;43m256\u001b[39;49m\u001b[43m,\u001b[49m\u001b[43m \u001b[49m\u001b[43mvalidation_data\u001b[49m\u001b[38;5;241;43m=\u001b[39;49m\u001b[43mtest_dataloader\u001b[49m\u001b[43m,\u001b[49m\u001b[43m \u001b[49m\u001b[43mepochs\u001b[49m\u001b[38;5;241;43m=\u001b[39;49m\u001b[38;5;241;43m1\u001b[39;49m\u001b[43m)\u001b[49m\n",
      "File \u001b[0;32m~/anaconda3/lib/python3.8/site-packages/keras/src/utils/traceback_utils.py:70\u001b[0m, in \u001b[0;36mfilter_traceback.<locals>.error_handler\u001b[0;34m(*args, **kwargs)\u001b[0m\n\u001b[1;32m     67\u001b[0m     filtered_tb \u001b[38;5;241m=\u001b[39m _process_traceback_frames(e\u001b[38;5;241m.\u001b[39m__traceback__)\n\u001b[1;32m     68\u001b[0m     \u001b[38;5;66;03m# To get the full stack trace, call:\u001b[39;00m\n\u001b[1;32m     69\u001b[0m     \u001b[38;5;66;03m# `tf.debugging.disable_traceback_filtering()`\u001b[39;00m\n\u001b[0;32m---> 70\u001b[0m     \u001b[38;5;28;01mraise\u001b[39;00m e\u001b[38;5;241m.\u001b[39mwith_traceback(filtered_tb) \u001b[38;5;28;01mfrom\u001b[39;00m \u001b[38;5;28;01mNone\u001b[39;00m\n\u001b[1;32m     71\u001b[0m \u001b[38;5;28;01mfinally\u001b[39;00m:\n\u001b[1;32m     72\u001b[0m     \u001b[38;5;28;01mdel\u001b[39;00m filtered_tb\n",
      "File \u001b[0;32m~/anaconda3/lib/python3.8/site-packages/keras/src/engine/data_adapter.py:1105\u001b[0m, in \u001b[0;36mselect_data_adapter\u001b[0;34m(x, y)\u001b[0m\n\u001b[1;32m   1102\u001b[0m adapter_cls \u001b[38;5;241m=\u001b[39m [\u001b[38;5;28mcls\u001b[39m \u001b[38;5;28;01mfor\u001b[39;00m \u001b[38;5;28mcls\u001b[39m \u001b[38;5;129;01min\u001b[39;00m ALL_ADAPTER_CLS \u001b[38;5;28;01mif\u001b[39;00m \u001b[38;5;28mcls\u001b[39m\u001b[38;5;241m.\u001b[39mcan_handle(x, y)]\n\u001b[1;32m   1103\u001b[0m \u001b[38;5;28;01mif\u001b[39;00m \u001b[38;5;129;01mnot\u001b[39;00m adapter_cls:\n\u001b[1;32m   1104\u001b[0m     \u001b[38;5;66;03m# TODO(scottzhu): This should be a less implementation-specific error.\u001b[39;00m\n\u001b[0;32m-> 1105\u001b[0m     \u001b[38;5;28;01mraise\u001b[39;00m \u001b[38;5;167;01mValueError\u001b[39;00m(\n\u001b[1;32m   1106\u001b[0m         \u001b[38;5;124m\"\u001b[39m\u001b[38;5;124mFailed to find data adapter that can handle input: \u001b[39m\u001b[38;5;132;01m{}\u001b[39;00m\u001b[38;5;124m, \u001b[39m\u001b[38;5;132;01m{}\u001b[39;00m\u001b[38;5;124m\"\u001b[39m\u001b[38;5;241m.\u001b[39mformat(\n\u001b[1;32m   1107\u001b[0m             _type_name(x), _type_name(y)\n\u001b[1;32m   1108\u001b[0m         )\n\u001b[1;32m   1109\u001b[0m     )\n\u001b[1;32m   1110\u001b[0m \u001b[38;5;28;01melif\u001b[39;00m \u001b[38;5;28mlen\u001b[39m(adapter_cls) \u001b[38;5;241m>\u001b[39m \u001b[38;5;241m1\u001b[39m:\n\u001b[1;32m   1111\u001b[0m     \u001b[38;5;28;01mraise\u001b[39;00m \u001b[38;5;167;01mRuntimeError\u001b[39;00m(\n\u001b[1;32m   1112\u001b[0m         \u001b[38;5;124m\"\u001b[39m\u001b[38;5;124mData adapters should be mutually exclusive for \u001b[39m\u001b[38;5;124m\"\u001b[39m\n\u001b[1;32m   1113\u001b[0m         \u001b[38;5;124m\"\u001b[39m\u001b[38;5;124mhandling inputs. Found multiple adapters \u001b[39m\u001b[38;5;132;01m{}\u001b[39;00m\u001b[38;5;124m to handle \u001b[39m\u001b[38;5;124m\"\u001b[39m\n\u001b[1;32m   1114\u001b[0m         \u001b[38;5;124m\"\u001b[39m\u001b[38;5;124minput: \u001b[39m\u001b[38;5;132;01m{}\u001b[39;00m\u001b[38;5;124m, \u001b[39m\u001b[38;5;132;01m{}\u001b[39;00m\u001b[38;5;124m\"\u001b[39m\u001b[38;5;241m.\u001b[39mformat(adapter_cls, _type_name(x), _type_name(y))\n\u001b[1;32m   1115\u001b[0m     )\n",
      "\u001b[0;31mValueError\u001b[0m: Failed to find data adapter that can handle input: <class 'torch.utils.data.dataloader.DataLoader'>, <class 'NoneType'>"
     ]
    }
   ],
   "source": [
    "history = model.fit(train_dataloader, batch_size=256, validation_data=test_dataloader, epochs=1)"
   ]
  },
  {
   "cell_type": "code",
   "execution_count": 11,
   "id": "7c7269e5-da92-456d-a93a-7818906d28c4",
   "metadata": {},
   "outputs": [],
   "source": [
    "# model = keras.Sequential([\n",
    "#   keras.Input(shape=(200, 7)),\n",
    "#   layers.Flatten(),\n",
    "#   layers.Dense(64, activation='relu'),\n",
    "#   layers.Dense(8, activation='relu'),\n",
    "#   layers.Dense(1, activation='sigmoid'),\n",
    "# ])\n",
    "# model.compile(loss=\"binary_crossentropy\", optimizer=\"adam\", metrics=[\"accuracy\", \"AUC\"])"
   ]
  },
  {
   "cell_type": "code",
   "execution_count": 12,
   "id": "bf47922e-416c-438a-8e99-0e6db5d899bc",
   "metadata": {},
   "outputs": [
    {
     "name": "stderr",
     "output_type": "stream",
     "text": [
      "2023-10-18 12:54:12.598772: I tensorflow/compiler/xla/service/service.cc:168] XLA service 0x7fb96c001dd0 initialized for platform CUDA (this does not guarantee that XLA will be used). Devices:\n",
      "2023-10-18 12:54:12.598833: I tensorflow/compiler/xla/service/service.cc:176]   StreamExecutor device (0): NVIDIA A40, Compute Capability 8.6\n",
      "2023-10-18 12:54:12.631852: I tensorflow/compiler/mlir/tensorflow/utils/dump_mlir_util.cc:255] disabling MLIR crash reproducer, set env var `MLIR_CRASH_REPRODUCER_DIRECTORY` to enable.\n",
      "2023-10-18 12:54:14.344489: E tensorflow/compiler/xla/stream_executor/cuda/cuda_dnn.cc:425] Loaded runtime CuDNN library: 8.5.0 but source was compiled with: 8.6.0.  CuDNN library needs to have matching major version and equal or higher minor version. If using a binary install, upgrade your CuDNN library.  If building from sources, make sure the library loaded at runtime is compatible with the version specified during compile configuration.\n",
      "2023-10-18 12:54:14.348252: W tensorflow/core/framework/op_kernel.cc:1828] OP_REQUIRES failed at xla_ops.cc:503 : FAILED_PRECONDITION: DNN library initialization failed. Look at the errors above for more details.\n"
     ]
    },
    {
     "ename": "FailedPreconditionError",
     "evalue": "Graph execution error:\n\nDetected at node 'StatefulPartitionedCall' defined at (most recent call last):\n    File \"/global/home/users/mfong/anaconda3/lib/python3.8/runpy.py\", line 194, in _run_module_as_main\n      return _run_code(code, main_globals, None,\n    File \"/global/home/users/mfong/anaconda3/lib/python3.8/runpy.py\", line 87, in _run_code\n      exec(code, run_globals)\n    File \"/global/home/users/mfong/anaconda3/lib/python3.8/site-packages/ipykernel_launcher.py\", line 17, in <module>\n      app.launch_new_instance()\n    File \"/global/home/users/mfong/anaconda3/lib/python3.8/site-packages/traitlets/config/application.py\", line 992, in launch_instance\n      app.start()\n    File \"/global/home/users/mfong/anaconda3/lib/python3.8/site-packages/ipykernel/kernelapp.py\", line 711, in start\n      self.io_loop.start()\n    File \"/global/home/users/mfong/anaconda3/lib/python3.8/site-packages/tornado/platform/asyncio.py\", line 215, in start\n      self.asyncio_loop.run_forever()\n    File \"/global/home/users/mfong/anaconda3/lib/python3.8/asyncio/base_events.py\", line 570, in run_forever\n      self._run_once()\n    File \"/global/home/users/mfong/anaconda3/lib/python3.8/asyncio/base_events.py\", line 1859, in _run_once\n      handle._run()\n    File \"/global/home/users/mfong/anaconda3/lib/python3.8/asyncio/events.py\", line 81, in _run\n      self._context.run(self._callback, *self._args)\n    File \"/global/home/users/mfong/anaconda3/lib/python3.8/site-packages/ipykernel/kernelbase.py\", line 510, in dispatch_queue\n      await self.process_one()\n    File \"/global/home/users/mfong/anaconda3/lib/python3.8/site-packages/ipykernel/kernelbase.py\", line 499, in process_one\n      await dispatch(*args)\n    File \"/global/home/users/mfong/anaconda3/lib/python3.8/site-packages/ipykernel/kernelbase.py\", line 406, in dispatch_shell\n      await result\n    File \"/global/home/users/mfong/anaconda3/lib/python3.8/site-packages/ipykernel/kernelbase.py\", line 729, in execute_request\n      reply_content = await reply_content\n    File \"/global/home/users/mfong/anaconda3/lib/python3.8/site-packages/ipykernel/ipkernel.py\", line 411, in do_execute\n      res = shell.run_cell(\n    File \"/global/home/users/mfong/anaconda3/lib/python3.8/site-packages/ipykernel/zmqshell.py\", line 531, in run_cell\n      return super().run_cell(*args, **kwargs)\n    File \"/global/home/users/mfong/anaconda3/lib/python3.8/site-packages/IPython/core/interactiveshell.py\", line 3006, in run_cell\n      result = self._run_cell(\n    File \"/global/home/users/mfong/anaconda3/lib/python3.8/site-packages/IPython/core/interactiveshell.py\", line 3061, in _run_cell\n      result = runner(coro)\n    File \"/global/home/users/mfong/anaconda3/lib/python3.8/site-packages/IPython/core/async_helpers.py\", line 129, in _pseudo_sync_runner\n      coro.send(None)\n    File \"/global/home/users/mfong/anaconda3/lib/python3.8/site-packages/IPython/core/interactiveshell.py\", line 3266, in run_cell_async\n      has_raised = await self.run_ast_nodes(code_ast.body, cell_name,\n    File \"/global/home/users/mfong/anaconda3/lib/python3.8/site-packages/IPython/core/interactiveshell.py\", line 3445, in run_ast_nodes\n      if await self.run_code(code, result, async_=asy):\n    File \"/global/home/users/mfong/anaconda3/lib/python3.8/site-packages/IPython/core/interactiveshell.py\", line 3505, in run_code\n      exec(code_obj, self.user_global_ns, self.user_ns)\n    File \"/tmp/ipykernel_8126/3905653414.py\", line 1, in <module>\n      model.fit(train_dataloader, batch_size=256, validation_data=test_dataloader, epochs=1)\n    File \"/global/home/users/mfong/anaconda3/lib/python3.8/site-packages/keras_core/src/utils/traceback_utils.py\", line 118, in error_handler\n      return fn(*args, **kwargs)\n    File \"/global/home/users/mfong/anaconda3/lib/python3.8/site-packages/keras_core/src/backend/tensorflow/trainer.py\", line 320, in fit\n      logs = self.train_function(iterator)\n    File \"/global/home/users/mfong/anaconda3/lib/python3.8/site-packages/keras_core/src/backend/tensorflow/trainer.py\", line 115, in one_step_on_iterator\n      outputs = self.distribute_strategy.run(\nNode: 'StatefulPartitionedCall'\nDNN library initialization failed. Look at the errors above for more details.\n\t [[{{node StatefulPartitionedCall}}]] [Op:__inference_one_step_on_iterator_1876]",
     "output_type": "error",
     "traceback": [
      "\u001b[0;31m---------------------------------------------------------------------------\u001b[0m",
      "\u001b[0;31mFailedPreconditionError\u001b[0m                   Traceback (most recent call last)",
      "Cell \u001b[0;32mIn[12], line 1\u001b[0m\n\u001b[0;32m----> 1\u001b[0m \u001b[43mmodel\u001b[49m\u001b[38;5;241;43m.\u001b[39;49m\u001b[43mfit\u001b[49m\u001b[43m(\u001b[49m\u001b[43mtrain_dataloader\u001b[49m\u001b[43m,\u001b[49m\u001b[43m \u001b[49m\u001b[43mbatch_size\u001b[49m\u001b[38;5;241;43m=\u001b[39;49m\u001b[38;5;241;43m256\u001b[39;49m\u001b[43m,\u001b[49m\u001b[43m \u001b[49m\u001b[43mvalidation_data\u001b[49m\u001b[38;5;241;43m=\u001b[39;49m\u001b[43mtest_dataloader\u001b[49m\u001b[43m,\u001b[49m\u001b[43m \u001b[49m\u001b[43mepochs\u001b[49m\u001b[38;5;241;43m=\u001b[39;49m\u001b[38;5;241;43m1\u001b[39;49m\u001b[43m)\u001b[49m\n\u001b[1;32m      2\u001b[0m model\u001b[38;5;241m.\u001b[39mevaluate(val_dataloader)\n",
      "File \u001b[0;32m~/anaconda3/lib/python3.8/site-packages/keras_core/src/utils/traceback_utils.py:123\u001b[0m, in \u001b[0;36mfilter_traceback.<locals>.error_handler\u001b[0;34m(*args, **kwargs)\u001b[0m\n\u001b[1;32m    120\u001b[0m     filtered_tb \u001b[38;5;241m=\u001b[39m _process_traceback_frames(e\u001b[38;5;241m.\u001b[39m__traceback__)\n\u001b[1;32m    121\u001b[0m     \u001b[38;5;66;03m# To get the full stack trace, call:\u001b[39;00m\n\u001b[1;32m    122\u001b[0m     \u001b[38;5;66;03m# `keras_core.config.disable_traceback_filtering()`\u001b[39;00m\n\u001b[0;32m--> 123\u001b[0m     \u001b[38;5;28;01mraise\u001b[39;00m e\u001b[38;5;241m.\u001b[39mwith_traceback(filtered_tb) \u001b[38;5;28;01mfrom\u001b[39;00m \u001b[38;5;28;01mNone\u001b[39;00m\n\u001b[1;32m    124\u001b[0m \u001b[38;5;28;01mfinally\u001b[39;00m:\n\u001b[1;32m    125\u001b[0m     \u001b[38;5;28;01mdel\u001b[39;00m filtered_tb\n",
      "File \u001b[0;32m~/anaconda3/lib/python3.8/site-packages/tensorflow/python/eager/execute.py:53\u001b[0m, in \u001b[0;36mquick_execute\u001b[0;34m(op_name, num_outputs, inputs, attrs, ctx, name)\u001b[0m\n\u001b[1;32m     51\u001b[0m \u001b[38;5;28;01mtry\u001b[39;00m:\n\u001b[1;32m     52\u001b[0m   ctx\u001b[38;5;241m.\u001b[39mensure_initialized()\n\u001b[0;32m---> 53\u001b[0m   tensors \u001b[38;5;241m=\u001b[39m pywrap_tfe\u001b[38;5;241m.\u001b[39mTFE_Py_Execute(ctx\u001b[38;5;241m.\u001b[39m_handle, device_name, op_name,\n\u001b[1;32m     54\u001b[0m                                       inputs, attrs, num_outputs)\n\u001b[1;32m     55\u001b[0m \u001b[38;5;28;01mexcept\u001b[39;00m core\u001b[38;5;241m.\u001b[39m_NotOkStatusException \u001b[38;5;28;01mas\u001b[39;00m e:\n\u001b[1;32m     56\u001b[0m   \u001b[38;5;28;01mif\u001b[39;00m name \u001b[38;5;129;01mis\u001b[39;00m \u001b[38;5;129;01mnot\u001b[39;00m \u001b[38;5;28;01mNone\u001b[39;00m:\n",
      "\u001b[0;31mFailedPreconditionError\u001b[0m: Graph execution error:\n\nDetected at node 'StatefulPartitionedCall' defined at (most recent call last):\n    File \"/global/home/users/mfong/anaconda3/lib/python3.8/runpy.py\", line 194, in _run_module_as_main\n      return _run_code(code, main_globals, None,\n    File \"/global/home/users/mfong/anaconda3/lib/python3.8/runpy.py\", line 87, in _run_code\n      exec(code, run_globals)\n    File \"/global/home/users/mfong/anaconda3/lib/python3.8/site-packages/ipykernel_launcher.py\", line 17, in <module>\n      app.launch_new_instance()\n    File \"/global/home/users/mfong/anaconda3/lib/python3.8/site-packages/traitlets/config/application.py\", line 992, in launch_instance\n      app.start()\n    File \"/global/home/users/mfong/anaconda3/lib/python3.8/site-packages/ipykernel/kernelapp.py\", line 711, in start\n      self.io_loop.start()\n    File \"/global/home/users/mfong/anaconda3/lib/python3.8/site-packages/tornado/platform/asyncio.py\", line 215, in start\n      self.asyncio_loop.run_forever()\n    File \"/global/home/users/mfong/anaconda3/lib/python3.8/asyncio/base_events.py\", line 570, in run_forever\n      self._run_once()\n    File \"/global/home/users/mfong/anaconda3/lib/python3.8/asyncio/base_events.py\", line 1859, in _run_once\n      handle._run()\n    File \"/global/home/users/mfong/anaconda3/lib/python3.8/asyncio/events.py\", line 81, in _run\n      self._context.run(self._callback, *self._args)\n    File \"/global/home/users/mfong/anaconda3/lib/python3.8/site-packages/ipykernel/kernelbase.py\", line 510, in dispatch_queue\n      await self.process_one()\n    File \"/global/home/users/mfong/anaconda3/lib/python3.8/site-packages/ipykernel/kernelbase.py\", line 499, in process_one\n      await dispatch(*args)\n    File \"/global/home/users/mfong/anaconda3/lib/python3.8/site-packages/ipykernel/kernelbase.py\", line 406, in dispatch_shell\n      await result\n    File \"/global/home/users/mfong/anaconda3/lib/python3.8/site-packages/ipykernel/kernelbase.py\", line 729, in execute_request\n      reply_content = await reply_content\n    File \"/global/home/users/mfong/anaconda3/lib/python3.8/site-packages/ipykernel/ipkernel.py\", line 411, in do_execute\n      res = shell.run_cell(\n    File \"/global/home/users/mfong/anaconda3/lib/python3.8/site-packages/ipykernel/zmqshell.py\", line 531, in run_cell\n      return super().run_cell(*args, **kwargs)\n    File \"/global/home/users/mfong/anaconda3/lib/python3.8/site-packages/IPython/core/interactiveshell.py\", line 3006, in run_cell\n      result = self._run_cell(\n    File \"/global/home/users/mfong/anaconda3/lib/python3.8/site-packages/IPython/core/interactiveshell.py\", line 3061, in _run_cell\n      result = runner(coro)\n    File \"/global/home/users/mfong/anaconda3/lib/python3.8/site-packages/IPython/core/async_helpers.py\", line 129, in _pseudo_sync_runner\n      coro.send(None)\n    File \"/global/home/users/mfong/anaconda3/lib/python3.8/site-packages/IPython/core/interactiveshell.py\", line 3266, in run_cell_async\n      has_raised = await self.run_ast_nodes(code_ast.body, cell_name,\n    File \"/global/home/users/mfong/anaconda3/lib/python3.8/site-packages/IPython/core/interactiveshell.py\", line 3445, in run_ast_nodes\n      if await self.run_code(code, result, async_=asy):\n    File \"/global/home/users/mfong/anaconda3/lib/python3.8/site-packages/IPython/core/interactiveshell.py\", line 3505, in run_code\n      exec(code_obj, self.user_global_ns, self.user_ns)\n    File \"/tmp/ipykernel_8126/3905653414.py\", line 1, in <module>\n      model.fit(train_dataloader, batch_size=256, validation_data=test_dataloader, epochs=1)\n    File \"/global/home/users/mfong/anaconda3/lib/python3.8/site-packages/keras_core/src/utils/traceback_utils.py\", line 118, in error_handler\n      return fn(*args, **kwargs)\n    File \"/global/home/users/mfong/anaconda3/lib/python3.8/site-packages/keras_core/src/backend/tensorflow/trainer.py\", line 320, in fit\n      logs = self.train_function(iterator)\n    File \"/global/home/users/mfong/anaconda3/lib/python3.8/site-packages/keras_core/src/backend/tensorflow/trainer.py\", line 115, in one_step_on_iterator\n      outputs = self.distribute_strategy.run(\nNode: 'StatefulPartitionedCall'\nDNN library initialization failed. Look at the errors above for more details.\n\t [[{{node StatefulPartitionedCall}}]] [Op:__inference_one_step_on_iterator_1876]"
     ]
    }
   ],
   "source": [
    "# model.fit(train_dataloader, batch_size=256, validation_data=test_dataloader, epochs=1)\n",
    "# model.evaluate(val_dataloader)"
   ]
  },
  {
   "cell_type": "code",
   "execution_count": null,
   "id": "c2b90e94-3901-49f3-b51c-285d2ea7c7a3",
   "metadata": {},
   "outputs": [],
   "source": []
  }
 ],
 "metadata": {
  "kernelspec": {
   "display_name": "Python 3 (ipykernel)",
   "language": "python",
   "name": "python3"
  },
  "language_info": {
   "codemirror_mode": {
    "name": "ipython",
    "version": 3
   },
   "file_extension": ".py",
   "mimetype": "text/x-python",
   "name": "python",
   "nbconvert_exporter": "python",
   "pygments_lexer": "ipython3",
   "version": "3.8.5"
  }
 },
 "nbformat": 4,
 "nbformat_minor": 5
}
